Workbook
Name UPDATE: 'Data Sheet'!$E$1

Sheet Instructions
A9: TechnoFunda Investing Excel Analysis - Version 3.0
A11: STEPS TO USE THIS ANALYSIS EXCEL
A12: 1 >> This excel is customised to be used only on Screener.in website. You might need to create free account on the website to be able to use it.
A13: 2>> Once you sign-up on Screener.in webite, go to this URL >> https://www.screener.in/excel/
A14: 3>> Upload this excel template there and it's DONE…!! Now in future all the time you will be able to use this template on Screener.in when you visit any company on the website.
A15: 4>> When you are on company tab on Screener.in website, simply click on "Export To Excel" option and you will be able to download output in exact same template which you have uploaded. It works like MAGIC :)
A16: Visit my website >> https://vivekmashrani.com/ to get lot of other insights on Investing. Cheers…!!
A19: READ THESE INSTRUCTIONS BEFORE YOU START
A20: 1. DON’T change anything on "Data Sheet" tab - this is dynamic template based on which company data we need is being pulled through Screener.in upload
A21: 2. If you see data is not flowing when you download excel from Screener.in, just click on "Enable Editing" on the top of your excel workbook
A23: Data Sheet underlying data is from Screener.in
A31: DISCLAIMER
... A35: Read full disclaimer and privacy policy here >> https://vivekmashrani.com/disclaimer-and-privacy-policy/

Sheet Overview
A2: NAVIGATION MENU
O6: Key Items | P6: Details
O7: Company Name | P7: ='Data Sheet'!B1 -> VINATI ORGANICS LTD
O8: Current Price (INR) | P8: ='Data Sheet'!B8 -> 1988.05
O9: No. of Shares (crores) | P9: ='Data Sheet'!B6 -> 10.278207
O10: Market Cap (crores) | P10: ='Data Sheet'!B9 -> 20433.59
O11: TTM Net Profit (crores) | P11: =SUM('Data Sheet'!H49:K49) -> 401.57
O12: TTM P/E ratio | P12: =P10/P11 -> 50.884254
O13: TTM Operating Profit Margin | P13: ='Ratio Analysis'!L4 -> 0.26503774
O14: Latest FY ROAE | P14: ='Ratio Analysis'!K16 -> 0.20564368
O15: Latest FY ROACE | P15: ='Ratio Analysis'!K17 -> 0.2658919

Sheet Income Statement
A1: Income Statement Analysis
A2: COMPANY NAME >> | B2: =+'Data Sheet'!B1 -> VINATI ORGANICS LTD | M2: GROWTH TREND ANALYSIS
A3: INR (in crores) | B3: =+'Data Sheet'!B16 -> 41364 | C3: =+'Data Sheet'!C16 -> 41729 | D3: =+'Data Sheet'!D16 -> 42094 | E3: =+'Data Sheet'!E16 -> 42460 | F3: =+'Data Sheet'!F16 -> 42825 | G3: =+'Data Sheet'!G16 -> 43190 | H3: =+'Data Sheet'!H16 -> 43555 | I3: =+'Data Sheet'!I16 -> 43921 | ... K3: =+'Data Sheet'!K16 -> 44651 | L3: TTM | M3: 9 | N3: 5 | O3: 3
A4: Sales | B4: =+'Data Sheet'!B17 -> 554.27 | C4: =+'Data Sheet'!C17 -> 696.13 | D4: =+'Data Sheet'!D17 -> 771.73 | E4: =+'Data Sheet'!E17 -> 630.95 | F4: =+'Data Sheet'!F17 -> 640.79 | G4: =+'Data Sheet'!G17 -> 729.68 | H4: =+'Data Sheet'!H17 -> 1127.92 | I4: =+'Data Sheet'!I17 -> 1028.87 | ... K4: =+'Data Sheet'!K17 -> 1615.51 | L4: =SUM('Data Sheet'!H42:K42) -> 1927.65 | M4: =IFERROR((K4/B4)^(1/$M$3)-1,"n/m") -> 0.12621399 | N4: =IFERROR((K4/F4)^(1/$N$3)-1,"n/m") -> 0.20314726 | O4: =IFERROR((K4/H4)^(1/$O$3)-1,"n/m") -> 0.12722458
A5: Operating Profit | B5: =SUM('Data Sheet'!B17-'Data Sheet'!B18+'Data Sheet'!B19)-SUM('Data Sheet'!B20:B24) -> 120.34 | C5: =SUM('Data Sheet'!C17-'Data Sheet'!C18+'Data Sheet'!C19)-SUM('Data Sheet'!C20:C24) -> 152.89 | D5: =SUM('Data Sheet'!D17-'Data Sheet'!D18+'Data Sheet'!D19)-SUM('Data Sheet'!D20:D24) -> 192.1 | E5: =SUM('Data Sheet'!E17-'Data Sheet'!E18+'Data Sheet'!E19)-SUM('Data Sheet'!E20:E24) -> 206.85 | F5: =SUM('Data Sheet'!F17-'Data Sheet'!F18+'Data Sheet'!F19)-SUM('Data Sheet'!F20:F24) -> 217.84 | G5: =SUM('Data Sheet'!G17-'Data Sheet'!G18+'Data Sheet'!G19)-SUM('Data Sheet'!G20:G24) -> 198.29 | H5: =SUM('Data Sheet'!H17-'Data Sheet'!H18+'Data Sheet'!H19)-SUM('Data Sheet'!H20:H24) -> 425.01 | I5: =SUM('Data Sheet'!I17-'Data Sheet'!I18+'Data Sheet'!I19)-SUM('Data Sheet'!I20:I24) -> 414.89 | ... K5: =SUM('Data Sheet'!K17-'Data Sheet'!K18+'Data Sheet'!K19)-SUM('Data Sheet'!K20:K24) -> 435.48 | L5: =SUM('Data Sheet'!H50:K50) -> 510.9 | M5: =IFERROR((K5/B5)^(1/$M$3)-1,"n/m") -> 0.153618 | N5: =IFERROR((K5/F5)^(1/$N$3)-1,"n/m") -> 0.14859287 | O5: =IFERROR((K5/H5)^(1/$O$3)-1,"n/m") -> 0.0081450495
A6: Other Income | B6: =+'Data Sheet'!B25 -> 3.76 | C6: =+'Data Sheet'!C25 -> 9.17 | D6: =+'Data Sheet'!D25 -> 8.82 | E6: =+'Data Sheet'!E25 -> 6.09 | F6: =+'Data Sheet'!F25 -> 12.48 | G6: =+'Data Sheet'!G25 -> 30.62 | H6: =+'Data Sheet'!H25 -> 29.8 | I6: =+'Data Sheet'!I25 -> 44.99 | ... K6: =+'Data Sheet'!K25 -> 60.96 | M6: =IFERROR((K6/B6)^(1/$M$3)-1,"n/m") -> 0.36278884 | N6: =IFERROR((K6/F6)^(1/$N$3)-1,"n/m") -> 0.37330207 | O6: =IFERROR((K6/H6)^(1/$O$3)-1,"n/m") -> 0.26943236
A7: EBITDA | B7: =+B6+B5 -> 124.1 | C7: =+C6+C5 -> 162.06 | D7: =+D6+D5 -> 200.92 | E7: =+E6+E5 -> 212.94 | F7: =+F6+F5 -> 230.32 | G7: =+G6+G5 -> 228.91 | H7: =+H6+H5 -> 454.81 | I7: =+I6+I5 -> 459.88 | ... K7: =+K6+K5 -> 496.44 | M7: =IFERROR((K7/B7)^(1/$M$3)-1,"n/m") -> 0.16653948 | N7: =IFERROR((K7/F7)^(1/$N$3)-1,"n/m") -> 0.16602275 | O7: =IFERROR((K7/H7)^(1/$O$3)-1,"n/m") -> 0.029624625
A8: Interest | B8: =-'Data Sheet'!B27 -> -11.54 | C8: =-'Data Sheet'!C27 -> -18.15 | D8: =-'Data Sheet'!D27 -> -9.76 | E8: =-'Data Sheet'!E27 -> -7.86 | F8: =-'Data Sheet'!F27 -> -2.75 | G8: =-'Data Sheet'!G27 -> -2.17 | H8: =-'Data Sheet'!H27 -> -2.18 | I8: =-'Data Sheet'!I27 -> -2.04 | ... K8: =-'Data Sheet'!K27 -> -1.65
A9: Depreciation | B9: =-'Data Sheet'!B26 -> -9.95 | C9: =-'Data Sheet'!C26 -> -15.32 | D9: =-'Data Sheet'!D26 -> -17.66 | E9: =-'Data Sheet'!E26 -> -18.52 | F9: =-'Data Sheet'!F26 -> -21.61 | G9: =-'Data Sheet'!G26 -> -23.36 | H9: =-'Data Sheet'!H26 -> -27.39 | I9: =-'Data Sheet'!I26 -> -33.16 | ... K9: =-'Data Sheet'!K26 -> -45.49
A10: Profit before tax (PBT) | B10: =+B7+B8+B9 -> 102.61 | C10: =+C7+C8+C9 -> 128.59 | D10: =+D7+D8+D9 -> 173.5 | E10: =+E7+E8+E9 -> 186.56 | F10: =+F7+F8+F9 -> 205.96 | G10: =+G7+G8+G9 -> 203.38 | H10: =+H7+H8+H9 -> 425.24 | I10: =+I7+I8+I9 -> 424.68 | ... K10: =+K7+K8+K9 -> 449.3 | L10: =SUM('Data Sheet'!H47:K47) -> 529.53 | M10: =IFERROR((K10/B10)^(1/$M$3)-1,"n/m") -> 0.17831321 | N10: =IFERROR((K10/F10)^(1/$N$3)-1,"n/m") -> 0.16882827 | O10: =IFERROR((K10/H10)^(1/$O$3)-1,"n/m") -> 0.018515016
A11: Tax | B11: =-'Data Sheet'!B29 -> -33.94 | C11: =-'Data Sheet'!C29 -> -42.43 | D11: =-'Data Sheet'!D29 -> -57.7 | E11: =-'Data Sheet'!E29 -> -54.99 | F11: =-'Data Sheet'!F29 -> -65.69 | G11: =-'Data Sheet'!G29 -> -59.5 | H11: =-'Data Sheet'!H29 -> -142.75 | I11: =-'Data Sheet'!I29 -> -90.84 | ... K11: =-'Data Sheet'!K29 -> -102.63
A12: Profit after tax (PAT) / Net Profit | B12: =+B11+B10 -> 68.67 | C12: =+C11+C10 -> 86.16 | D12: =+D11+D10 -> 115.8 | E12: =+E11+E10 -> 131.57 | F12: =+F11+F10 -> 140.27 | G12: =+G11+G10 -> 143.88 | H12: =+H11+H10 -> 282.49 | I12: =+I11+I10 -> 333.84 | ... K12: =+K11+K10 -> 346.67 | L12: =SUM('Data Sheet'!H49:K49) -> 401.57 | M12: =IFERROR((K12/B12)^(1/$M$3)-1,"n/m") -> 0.19709245 | N12: =IFERROR((K12/F12)^(1/$N$3)-1,"n/m") -> 0.19836825 | O12: =IFERROR((K12/H12)^(1/$O$3)-1,"n/m") -> 0.070625855
A14: Adjusted Equity Shares (in crores) | B14: =+'Data Sheet'!B93 -> 9.85 | C14: =+'Data Sheet'!C93 -> 9.85 | D14: =+'Data Sheet'!D93 -> 10.32 | E14: =+'Data Sheet'!E93 -> 10.32 | F14: =+'Data Sheet'!F93 -> 10.32 | G14: =+'Data Sheet'!G93 -> 10.28 | H14: =+'Data Sheet'!H93 -> 10.28 | I14: =+'Data Sheet'!I93 -> 10.28 | ... K14: =+'Data Sheet'!K93 -> 10.28
A16: Sales Growth YoY (%) | C16: =IF(B4>0,C4/B4-1,"n/m") -> 0.25594025 | D16: =IF(C4>0,D4/C4-1,"n/m") -> 0.10860041 | E16: =IF(D4>0,E4/D4-1,"n/m") -> -0.18242131 | F16: =IF(E4>0,F4/E4-1,"n/m") -> 0.015595531 | G16: =IF(F4>0,G4/F4-1,"n/m") -> 0.13871939 | H16: =IF(G4>0,H4/G4-1,"n/m") -> 0.54577349 | I16: =IF(H4>0,I4/H4-1,"n/m") -> -0.087816512 | J16: =IF(I4>0,J4/I4-1,"n/m") -> -0.07251645 | K16: =IF(J4>0,K4/J4-1,"n/m") -> 0.69294532
A17: EBIDTA Growth YoY (%) | C17: =IF(B7>0,C7/B7-1,"n/m") -> 0.30588235 | D17: =IF(C7>0,D7/C7-1,"n/m") -> 0.23978773 | E17: =IF(D7>0,E7/D7-1,"n/m") -> 0.059824806 | F17: =IF(E7>0,F7/E7-1,"n/m") -> 0.081619235 | G17: =IF(F7>0,G7/F7-1,"n/m") -> -0.0061219173 | H17: =IF(G7>0,H7/G7-1,"n/m") -> 0.98685073 | I17: =IF(H7>0,I7/H7-1,"n/m") -> 0.011147512 | J17: =IF(I7>0,J7/I7-1,"n/m") -> -0.17561103 | K17: =IF(J7>0,K7/J7-1,"n/m") -> 0.30945347
A18: PAT Growth YoY (%) | C18: =IF(B12>0,C12/B12-1,"n/m") -> 0.25469637 | D18: =IF(C12>0,D12/C12-1,"n/m") -> 0.34401114 | E18: =IF(D12>0,E12/D12-1,"n/m") -> 0.13618307 | F18: =IF(E12>0,F12/E12-1,"n/m") -> 0.066124496 | G18: =IF(F12>0,G12/F12-1,"n/m") -> 0.02573608 | H18: =IF(G12>0,H12/G12-1,"n/m") -> 0.96337225 | I18: =IF(H12>0,I12/H12-1,"n/m") -> 0.18177635 | J18: =IF(I12>0,J12/I12-1,"n/m") -> -0.19317637 | K18: =IF(J12>0,K12/J12-1,"n/m") -> 0.28706144
A20: Price | B20: ='Data Sheet'!B90 -> 51.88 | C20: ='Data Sheet'!C90 -> 140.53 | D20: ='Data Sheet'!D90 -> 261.95 | E20: ='Data Sheet'!E90 -> 194.53 | F20: ='Data Sheet'!F90 -> 379 | G20: ='Data Sheet'!G90 -> 451.28 | H20: ='Data Sheet'!H90 -> 822.18 | I20: ='Data Sheet'!I90 -> 774.55 | ... K20: ='Data Sheet'!K90 -> 1953.2 | M20: =IFERROR((K20/B20)^(1/$M$3)-1,"n/m") -> 0.49652154 | N20: =IFERROR((K20/F20)^(1/$N$3)-1,"n/m") -> 0.38810239 | O20: =IFERROR((K20/H20)^(1/$O$3)-1,"n/m") -> 0.33431982
A23: Operating Profit Margin (OPM) % | B23: =IF(B5>0,B5/B4,"n/m") -> 0.2171144 | C23: =IF(C5>0,C5/C4,"n/m") -> 0.21962852 | D23: =IF(D5>0,D5/D4,"n/m") -> 0.24892125 | E23: =IF(E5>0,E5/E4,"n/m") -> 0.32783897 | F23: =IF(F5>0,F5/F4,"n/m") -> 0.33995537 | G23: =IF(G5>0,G5/G4,"n/m") -> 0.27174926 | H23: =IF(H5>0,H5/H4,"n/m") -> 0.37680864 | I23: =IF(I5>0,I5/I4,"n/m") -> 0.40324822 | ... L23: =IF(L5>0,L5/L4,"n/m") -> 0.26503774
A24: Net Profit Margin (NPM) % | B24: =IF(B12>0,B12/B4,"n/m") -> 0.12389269 | C24: =IF(C12>0,C12/C4,"n/m") -> 0.12376999 | D24: =IF(D12>0,D12/D4,"n/m") -> 0.15005248 | E24: =IF(E12>0,E12/E4,"n/m") -> 0.20852682 | F24: =IF(F12>0,F12/F4,"n/m") -> 0.21890167 | G24: =IF(G12>0,G12/G4,"n/m") -> 0.19718233 | H24: =IF(H12>0,H12/H4,"n/m") -> 0.25045216 | I24: =IF(I12>0,I12/I4,"n/m") -> 0.32447248 | ... L24: =IF(L12>0,L12/L4,"n/m") -> 0.20832101
A25: Tax Payout % | B25: =IF(B11<0,-B11/B10,"n/m") -> 0.33076698 | C25: =IF(C11<0,-C11/C10,"n/m") -> 0.32996345 | D25: =IF(D11<0,-D11/D10,"n/m") -> 0.33256484 | E25: =IF(E11<0,-E11/E10,"n/m") -> 0.29475772 | F25: =IF(F11<0,-F11/F10,"n/m") -> 0.31894543 | G25: =IF(G11<0,-G11/G10,"n/m") -> 0.29255581 | H25: =IF(H11<0,-H11/H10,"n/m") -> 0.33569279 | I25: =IF(I11<0,-I11/I10,"n/m") -> 0.21390223 | ... K25: =IF(K11<0,-K11/K10,"n/m") -> 0.22842199
A26: Dividend Payout % | B26: =IF('Data Sheet'!B31>0,'Data Sheet'!B31/'Data Sheet'!B30,"n/m") -> 0.17972619 | C26: =IF('Data Sheet'!C31>0,'Data Sheet'!C31/'Data Sheet'!C30,"n/m") -> 0.17179338 | D26: =IF('Data Sheet'!D31>0,'Data Sheet'!D31/'Data Sheet'!D30,"n/m") -> 0.15597202 | E26: =IF('Data Sheet'!E31>0,'Data Sheet'!E31/'Data Sheet'!E30,"n/m") -> 0.15687467 | F26: =IF('Data Sheet'!F31>0,'Data Sheet'!F31/'Data Sheet'!F30,"n/m") -> 0.018391788 | G26: =IF('Data Sheet'!G31>0,'Data Sheet'!G31/'Data Sheet'!G30,"n/m") -> 0.16075897 | H26: =IF('Data Sheet'!H31>0,'Data Sheet'!H31/'Data Sheet'!H30,"n/m") -> 0.12736734 | I26: =IF('Data Sheet'!I31>0,'Data Sheet'!I31/'Data Sheet'!I30,"n/m") -> 0.16936764 | ... K26: =IF('Data Sheet'!K31>0,'Data Sheet'!K31/'Data Sheet'!K30,"n/m") -> 0.19274259
A27: Interest Coverage Ratio (x) | B27: =IFERROR((B10-B8)/(-B8),"n/m") -> 9.8916811 | C27: =IFERROR((C10-C8)/(-C8),"n/m") -> 8.0848485 | D27: =IFERROR((D10-D8)/(-D8),"n/m") -> 18.776639 | E27: =IFERROR((E10-E8)/(-E8),"n/m") -> 24.735369 | F27: =IFERROR((F10-F8)/(-F8),"n/m") -> 75.894545 | G27: =IFERROR((G10-G8)/(-G8),"n/m") -> 94.723502 | H27: =IFERROR((H10-H8)/(-H8),"n/m") -> 196.06422 | I27: =IFERROR((I10-I8)/(-I8),"n/m") -> 209.17647 | ... K27: =IFERROR((K10-K8)/(-K8),"n/m") -> 273.30303
A28: Earnings Per Share (EPS) | B28: =IFERROR(B12/B14,"n/m") -> 6.9715736 | C28: =IFERROR(C12/C14,"n/m") -> 8.7472081 | D28: =IFERROR(D12/D14,"n/m") -> 11.22093 | E28: =IFERROR(E12/E14,"n/m") -> 12.749031 | F28: =IFERROR(F12/F14,"n/m") -> 13.592054 | G28: =IFERROR(G12/G14,"n/m") -> 13.996109 | H28: =IFERROR(H12/H14,"n/m") -> 27.479572 | I28: =IFERROR(I12/I14,"n/m") -> 32.474708 | ... K28: =IFERROR(K12/K14,"n/m") -> 33.722763 | M28: =IFERROR((K28/B28)^(1/$M$3)-1,"n/m") -> 0.19142255 | N28: =IFERROR((K28/F28)^(1/$N$3)-1,"n/m") -> 0.19929938 | O28: =IFERROR((K28/H28)^(1/$O$3)-1,"n/m") -> 0.070625855
A29: PE Ratio (x) | B29: =IFERROR(B20/B28,"n/m") -> 7.4416485 | C29: =IFERROR(C20/C28,"n/m") -> 16.065698 | D29: =IFERROR(D20/D28,"n/m") -> 23.344767 | E29: =IFERROR(E20/E28,"n/m") -> 15.258415 | F29: =IFERROR(F20/F28,"n/m") -> 27.883938 | G29: =IFERROR(G20/G28,"n/m") -> 32.243247 | H29: =IFERROR(H20/H28,"n/m") -> 29.91968 | I29: =IFERROR(I20/I28,"n/m") -> 23.850869 | ... K29: =IFERROR(K20/K28,"n/m") -> 57.919335
A32: Common Sizing Expenses
A33: Year >> | B33: =+B3 -> 41364 | C33: =+C3 -> 41729 | D33: =+D3 -> 42094 | E33: =+E3 -> 42460 | F33: =+F3 -> 42825 | G33: =+G3 -> 43190 | H33: =+H3 -> 43555 | I33: =+I3 -> 43921 | ... K33: =+K3 -> 44651
A34: Sales | B34: ='Data Sheet'!B17/'Income Statement'!B$4 -> 1 | C34: ='Data Sheet'!C17/'Income Statement'!C$4 -> 1 | D34: ='Data Sheet'!D17/'Income Statement'!D$4 -> 1 | E34: ='Data Sheet'!E17/'Income Statement'!E$4 -> 1 | F34: ='Data Sheet'!F17/'Income Statement'!F$4 -> 1 | G34: ='Data Sheet'!G17/'Income Statement'!G$4 -> 1 | H34: ='Data Sheet'!H17/'Income Statement'!H$4 -> 1 | I34: ='Data Sheet'!I17/'Income Statement'!I$4 -> 1 | ... K34: ='Data Sheet'!K17/'Income Statement'!K$4 -> 1
A35: Raw material Expenses | B35: ='Data Sheet'!B18/'Income Statement'!B$4 -> 0.61314883 | C35: ='Data Sheet'!C18/'Income Statement'!C$4 -> 0.6004051 | D35: ='Data Sheet'!D18/'Income Statement'!D$4 -> 0.59073769 | E35: ='Data Sheet'!E18/'Income Statement'!E$4 -> 0.46843648 | F35: ='Data Sheet'!F18/'Income Statement'!F$4 -> 0.47773842 | G35: ='Data Sheet'!G18/'Income Statement'!G$4 -> 0.50777053 | H35: ='Data Sheet'!H18/'Income Statement'!H$4 -> 0.46864139 | I35: ='Data Sheet'!I18/'Income Statement'!I$4 -> 0.41939215 | ... K35: ='Data Sheet'!K18/'Income Statement'!K$4 -> 0.5330391
A36: Change in Inventory | B36: =-'Data Sheet'!B19/'Income Statement'!B$4 -> -0.0085337471 | C36: =-'Data Sheet'!C19/'Income Statement'!C$4 -> 0.0012210363 | D36: =-'Data Sheet'!D19/'Income Statement'!D$4 -> 0.00084226349 | E36: =-'Data Sheet'!E19/'Income Statement'!E$4 -> 0.0011886837 | F36: =-'Data Sheet'!F19/'Income Statement'!F$4 -> -0.0087080011 | G36: =-'Data Sheet'!G19/'Income Statement'!G$4 -> 0.0096617695 | H36: =-'Data Sheet'!H19/'Income Statement'!H$4 -> -0.0030941911 | I36: =-'Data Sheet'!I19/'Income Statement'!I$4 -> -0.0027117129 | ... K36: =-'Data Sheet'!K19/'Income Statement'!K$4 -> -0.00025378982
A37: Power and Fuel Cost | B37: ='Data Sheet'!B20/'Income Statement'!B$4 -> 0.05571292 | C37: ='Data Sheet'!C20/'Income Statement'!C$4 -> 0.0518294 | D37: ='Data Sheet'!D20/'Income Statement'!D$4 -> 0.0405971 | E37: ='Data Sheet'!E20/'Income Statement'!E$4 -> 0.049639433 | F37: ='Data Sheet'!F20/'Income Statement'!F$4 -> 0.057663197 | G37: ='Data Sheet'!G20/'Income Statement'!G$4 -> 0.065658919 | H37: ='Data Sheet'!H20/'Income Statement'!H$4 -> 0.049968083 | I37: ='Data Sheet'!I20/'Income Statement'!I$4 -> 0.051114329 | ... K37: ='Data Sheet'!K20/'Income Statement'!K$4 -> 0.074440889
A38: Other Mfr. Exp | B38: ='Data Sheet'!B21/'Income Statement'!B$4 -> 0.029137424 | C38: ='Data Sheet'!C21/'Income Statement'!C$4 -> 0.032249723 | D38: ='Data Sheet'!D21/'Income Statement'!D$4 -> 0.035128866 | E38: ='Data Sheet'!E21/'Income Statement'!E$4 -> 0.052682463 | F38: ='Data Sheet'!F21/'Income Statement'!F$4 -> 0.048174909 | G38: ='Data Sheet'!G21/'Income Statement'!G$4 -> 0.059080693 | H38: ='Data Sheet'!H21/'Income Statement'!H$4 -> 0.044497837 | I38: ='Data Sheet'!I21/'Income Statement'!I$4 -> 0.049005219 | ... K38: ='Data Sheet'!K21/'Income Statement'!K$4 -> 0.052905893
A39: Employee Cost | B39: ='Data Sheet'!B22/'Income Statement'!B$4 -> 0.040810435 | C39: ='Data Sheet'!C22/'Income Statement'!C$4 -> 0.03946102 | D39: ='Data Sheet'!D22/'Income Statement'!D$4 -> 0.041387532 | E39: ='Data Sheet'!E22/'Income Statement'!E$4 -> 0.05704097 | F39: ='Data Sheet'!F22/'Income Statement'!F$4 -> 0.065497277 | G39: ='Data Sheet'!G22/'Income Statement'!G$4 -> 0.067262362 | H39: ='Data Sheet'!H22/'Income Statement'!H$4 -> 0.048150578 | I39: ='Data Sheet'!I22/'Income Statement'!I$4 -> 0.062583222 | ... K39: ='Data Sheet'!K22/'Income Statement'!K$4 -> 0.052088814
A40: Selling and Admin Expenses | B40: ='Data Sheet'!B23/'Income Statement'!B$4 -> 0.041279521 | C40: ='Data Sheet'!C23/'Income Statement'!C$4 -> 0.037564823 | D40: ='Data Sheet'!D23/'Income Statement'!D$4 -> 0.030334443 | E40: ='Data Sheet'!E23/'Income Statement'!E$4 -> 0.026388779 | F40: ='Data Sheet'!F23/'Income Statement'!F$4 -> 0.010580689 | G40: ='Data Sheet'!G23/'Income Statement'!G$4 -> 0.011251508 | H40: ='Data Sheet'!H23/'Income Statement'!H$4 -> 0.0084757784 | I40: ='Data Sheet'!I23/'Income Statement'!I$4 -> 0.01022481 | ... K40: ='Data Sheet'!K23/'Income Statement'!K$4 -> 0.0083564942
A41: Other Expenses | B41: ='Data Sheet'!B24/'Income Statement'!B$4 -> 0.011330218 | C41: ='Data Sheet'!C24/'Income Statement'!C$4 -> 0.017640383 | D41: ='Data Sheet'!D24/'Income Statement'!D$4 -> 0.012050847 | E41: ='Data Sheet'!E24/'Income Statement'!E$4 -> 0.016784214 | F41: ='Data Sheet'!F24/'Income Statement'!F$4 -> 0.0090981445 | G41: ='Data Sheet'!G24/'Income Statement'!G$4 -> 0.00756496 | H41: ='Data Sheet'!H24/'Income Statement'!H$4 -> 0.0065518831 | I41: ='Data Sheet'!I24/'Income Statement'!I$4 -> 0.0071437597 | ... K41: ='Data Sheet'!K24/'Income Statement'!K$4 -> 0.0098606632
A42: Operating Profit Margin (OPM) % | B42: =B34-SUM(B35:B41) -> 0.2171144 | C42: =C34-SUM(C35:C41) -> 0.21962852 | D42: =D34-SUM(D35:D41) -> 0.24892125 | E42: =E34-SUM(E35:E41) -> 0.32783897 | F42: =F34-SUM(F35:F41) -> 0.33995537 | G42: =G34-SUM(G35:G41) -> 0.27174926 | H42: =H34-SUM(H35:H41) -> 0.37680864 | I42: =I34-SUM(I35:I41) -> 0.40324822 | ... K42: =K34-SUM(K35:K41) -> 0.26956193

Sheet Income Statement_Quarterly
A1: Income Statement Analysis - Quarterly
A2: COMPANY NAME >> | B2: =+'Data Sheet'!B1 -> VINATI ORGANICS LTD | L2: GROWTH TREND ANALYSIS
A3: INR (in crores) | B3: =+'Data Sheet'!B41 -> 44012 | C3: =+'Data Sheet'!C41 -> 44104 | D3: =+'Data Sheet'!D41 -> 44196 | E3: =+'Data Sheet'!E41 -> 44286 | F3: =+'Data Sheet'!F41 -> 44377 | G3: =+'Data Sheet'!G41 -> 44469 | H3: =+'Data Sheet'!H41 -> 44561 | I3: =+'Data Sheet'!I41 -> 44651 | ... K3: =+'Data Sheet'!K41 -> 44834 | M3: QoQ (Sequential) | N3: QoQ (Yearly)
A4: Sales | B4: =+'Data Sheet'!B42 -> 231.57 | C4: =+'Data Sheet'!C42 -> 219.44 | D4: =+'Data Sheet'!D42 -> 223.47 | E4: =+'Data Sheet'!E42 -> 279.77 | F4: =+'Data Sheet'!F42 -> 386.37 | G4: =+'Data Sheet'!G42 -> 374.1 | H4: =+'Data Sheet'!H42 -> 368.95 | I4: =+'Data Sheet'!I42 -> 486.09 | ... K4: =+'Data Sheet'!K42 -> 566.29 | M4: =IFERROR((K4/J4)-1,"n/m") -> 0.11844288 | N4: =IFERROR((K4/G4)-1,"n/m") -> 0.51373964
A5: Operating Profit | B5: =+'Data Sheet'!B50 -> 97.18 | C5: =+'Data Sheet'!C50 -> 84.13 | D5: =+'Data Sheet'!D50 -> 72.09 | E5: =+'Data Sheet'!E50 -> 99.12 | F5: =+'Data Sheet'!F50 -> 101.51 | G5: =+'Data Sheet'!G50 -> 101.01 | H5: =+'Data Sheet'!H50 -> 92.77 | I5: =+'Data Sheet'!I50 -> 138.78 | ... K5: =+'Data Sheet'!K50 -> 148.47 | M5: =IFERROR((K5/J5)-1,"n/m") -> 0.13439792 | N5: =IFERROR((K5/G5)-1,"n/m") -> 0.46985447
A6: Other Income | B6: =+'Data Sheet'!B44 -> 8.6 | C6: =+'Data Sheet'!C44 -> 1.4 | D6: =+'Data Sheet'!D44 -> 9.29 | E6: =+'Data Sheet'!E44 -> 6.57 | F6: =+'Data Sheet'!F44 -> 17.61 | G6: =+'Data Sheet'!G44 -> 13.58 | H6: =+'Data Sheet'!H44 -> 14.65 | I6: =+'Data Sheet'!I44 -> 15.13 | ... K6: =+'Data Sheet'!K44 -> 19.97 | M6: =IFERROR((K6/J6)-1,"n/m") -> 0.068485821 | N6: =IFERROR((K6/G6)-1,"n/m") -> 0.47054492
A7: EBITDA | B7: =+B6+B5 -> 105.78 | C7: =+C6+C5 -> 85.53 | D7: =+D6+D5 -> 81.38 | E7: =+E6+E5 -> 105.69 | F7: =+F6+F5 -> 119.12 | G7: =+G6+G5 -> 114.59 | H7: =+H6+H5 -> 107.42 | I7: =+I6+I5 -> 153.91 | ... K7: =+K6+K5 -> 168.44 | M7: =IFERROR((K7/J7)-1,"n/m") -> 0.12616166 | N7: =IFERROR((K7/G7)-1,"n/m") -> 0.46993629
A8: Interest | B8: =-'Data Sheet'!B46 -> -0.04 | C8: =-'Data Sheet'!C46 -> -0.05 | D8: =-'Data Sheet'!D46 -> -0.01 | E8: =-'Data Sheet'!E46 -> -0.11 | F8: =-'Data Sheet'!F46 -> -0.01 | G8: =-'Data Sheet'!G46 -> 0 | H8: =-'Data Sheet'!H46 -> -0.01 | I8: =-'Data Sheet'!I46 -> -0.23 | ... K8: =-'Data Sheet'!K46 -> -0.01
A9: Depreciation | B9: =-'Data Sheet'!B45 -> -10.65 | C9: =-'Data Sheet'!C45 -> -10.76 | D9: =-'Data Sheet'!D45 -> -10.77 | E9: =-'Data Sheet'!E45 -> -10.73 | F9: =-'Data Sheet'!F45 -> -11.01 | G9: =-'Data Sheet'!G45 -> -11.28 | H9: =-'Data Sheet'!H45 -> -11.52 | I9: =-'Data Sheet'!I45 -> -11.69 | ... K9: =-'Data Sheet'!K45 -> -13.05
A10: Profit before tax (PBT) | B10: =+B7+B8+B9 -> 95.09 | C10: =+C7+C8+C9 -> 74.72 | D10: =+D7+D8+D9 -> 70.6 | E10: =+E7+E8+E9 -> 94.85 | F10: =+F7+F8+F9 -> 108.1 | G10: =+G7+G8+G9 -> 103.31 | H10: =+H7+H8+H9 -> 95.89 | I10: =+I7+I8+I9 -> 141.99 | ... K10: =+K7+K8+K9 -> 155.38 | M10: =IFERROR((K10/J10)-1,"n/m") -> 0.1402363 | N10: =IFERROR((K10/G10)-1,"n/m") -> 0.50401704
A11: Tax | B11: =-'Data Sheet'!B48 -> -22.79 | C11: =-'Data Sheet'!C48 -> -12.68 | D11: =-'Data Sheet'!D48 -> -6.47 | E11: =-'Data Sheet'!E48 -> -23.99 | F11: =-'Data Sheet'!F48 -> -27.16 | G11: =-'Data Sheet'!G48 -> -21.95 | H11: =-'Data Sheet'!H48 -> -12.63 | I11: =-'Data Sheet'!I48 -> -40.89 | ... K11: =-'Data Sheet'!K48 -> -39.38
A12: Profit after tax (PAT) / Net Profit | B12: =+B11+B10 -> 72.3 | C12: =+C11+C10 -> 62.04 | D12: =+D11+D10 -> 64.13 | E12: =+E11+E10 -> 70.86 | F12: =+F11+F10 -> 80.94 | G12: =+G11+G10 -> 81.36 | H12: =+H11+H10 -> 83.26 | I12: =+I11+I10 -> 101.1 | ... K12: =+K11+K10 -> 116 | M12: =IFERROR((K12/J12)-1,"n/m") -> 0.14647163 | N12: =IFERROR((K12/G12)-1,"n/m") -> 0.42576205
A16: Operating Profit Margin (OPM) % | B16: =IF(B5>0,B5/B4,"n/m") -> 0.41965712 | C16: =IF(C5>0,C5/C4,"n/m") -> 0.38338498 | D16: =IF(D5>0,D5/D4,"n/m") -> 0.32259364 | E16: =IF(E5>0,E5/E4,"n/m") -> 0.35429102 | F16: =IF(F5>0,F5/F4,"n/m") -> 0.26272744 | G16: =IF(G5>0,G5/G4,"n/m") -> 0.27000802 | H16: =IF(H5>0,H5/H4,"n/m") -> 0.25144328 | I16: =IF(I5>0,I5/I4,"n/m") -> 0.28550268 | ... K16: =IF(K5>0,K5/K4,"n/m") -> 0.26218016
A17: Net Profit Margin (NPM) % | B17: =IF(B12>0,B12/B4,"n/m") -> 0.31221661 | C17: =IF(C12>0,C12/C4,"n/m") -> 0.28271965 | D17: =IF(D12>0,D12/D4,"n/m") -> 0.28697364 | E17: =IF(E12>0,E12/E4,"n/m") -> 0.25327948 | F17: =IF(F12>0,F12/F4,"n/m") -> 0.20948831 | G17: =IF(G12>0,G12/G4,"n/m") -> 0.21748196 | H17: =IF(H12>0,H12/H4,"n/m") -> 0.22566743 | I17: =IF(I12>0,I12/I4,"n/m") -> 0.20798618 | ... K17: =IF(K12>0,K12/K4,"n/m") -> 0.20484204
A18: Tax Payout % | B18: =IF(B11<0,-B11/B10,"n/m") -> 0.23966768 | C18: =IF(C11<0,-C11/C10,"n/m") -> 0.16970021 | D18: =IF(D11<0,-D11/D10,"n/m") -> 0.091643059 | E18: =IF(E11<0,-E11/E10,"n/m") -> 0.25292567 | F18: =IF(F11<0,-F11/F10,"n/m") -> 0.25124884 | G18: =IF(G11<0,-G11/G10,"n/m") -> 0.21246733 | H18: =IF(H11<0,-H11/H10,"n/m") -> 0.13171342 | I18: =IF(I11<0,-I11/I10,"n/m") -> 0.28797803 | ... K18: =IF(K11<0,-K11/K10,"n/m") -> 0.25344317
A19: Interest Coverage Ratio (x) | B19: =IFERROR((B10-B8)/(-B8),"n/m") -> 2378.25 | C19: =IFERROR((C10-C8)/(-C8),"n/m") -> 1495.4 | D19: =IFERROR((D10-D8)/(-D8),"n/m") -> 7061 | E19: =IFERROR((E10-E8)/(-E8),"n/m") -> 863.27273 | F19: =IFERROR((F10-F8)/(-F8),"n/m") -> 10811 | G19: =IFERROR((G10-G8)/(-G8),"n/m") -> n/m | H19: =IFERROR((H10-H8)/(-H8),"n/m") -> 9590 | I19: =IFERROR((I10-I8)/(-I8),"n/m") -> 618.34783 | ... K19: =IFERROR((K10-K8)/(-K8),"n/m") -> 15539

Sheet Balance Sheet
A1: Balance Sheet Analysis
A2: COMPANY NAME >> | B2: =+'Data Sheet'!B1 -> VINATI ORGANICS LTD | M2: AVERAGE TREND
A3: INR (in crores) | B3: =+'Data Sheet'!B16 -> 41364 | C3: =+'Data Sheet'!C16 -> 41729 | D3: =+'Data Sheet'!D16 -> 42094 | E3: =+'Data Sheet'!E16 -> 42460 | F3: =+'Data Sheet'!F16 -> 42825 | G3: =+'Data Sheet'!G16 -> 43190 | H3: =+'Data Sheet'!H16 -> 43555 | I3: =+'Data Sheet'!I16 -> 43921 | ... K3: =+'Data Sheet'!K16 -> 44651 | M3: 9 | N3: 5 | O3: 3
A4: Equity Share Capital | B4: =+'Data Sheet'!B57 -> 9.87 | C4: =+'Data Sheet'!C57 -> 9.87 | D4: =+'Data Sheet'!D57 -> 10.32 | E4: =+'Data Sheet'!E57 -> 10.32 | F4: =+'Data Sheet'!F57 -> 10.32 | G4: =+'Data Sheet'!G57 -> 10.28 | H4: =+'Data Sheet'!H57 -> 10.28 | I4: =+'Data Sheet'!I57 -> 10.28 | ... K4: =+'Data Sheet'!K57 -> 10.28
A5: Reserves | B5: =+'Data Sheet'!B58 -> 231.37 | C5: =+'Data Sheet'!C58 -> 300.2 | D5: =+'Data Sheet'!D58 -> 423.73 | E5: =+'Data Sheet'!E58 -> 530.46 | F5: =+'Data Sheet'!F58 -> 669.69 | G5: =+'Data Sheet'!G58 -> 786.39 | H5: =+'Data Sheet'!H58 -> 1041 | I5: =+'Data Sheet'!I58 -> 1269.13 | ... K5: =+'Data Sheet'!K58 -> 1817.86
A6: Borrowings | B6: =+'Data Sheet'!B59 -> 237.26 | C6: =+'Data Sheet'!C59 -> 161.58 | D6: =+'Data Sheet'!D59 -> 65.3 | E6: =+'Data Sheet'!E59 -> 42.07 | F6: =+'Data Sheet'!F59 -> 2.32 | G6: =+'Data Sheet'!G59 -> 15.2 | H6: =+'Data Sheet'!H59 -> 3.68 | I6: =+'Data Sheet'!I59 -> 0.35 | ... K6: =+'Data Sheet'!K59 -> 18.4
A7: Other Liabilities | B7: =+'Data Sheet'!B60 -> 67.13 | C7: =+'Data Sheet'!C60 -> 80.46 | D7: =+'Data Sheet'!D60 -> 99.84 | E7: =+'Data Sheet'!E60 -> 104.11 | F7: =+'Data Sheet'!F60 -> 138.8 | G7: =+'Data Sheet'!G60 -> 168.08 | H7: =+'Data Sheet'!H60 -> 172.62 | I7: =+'Data Sheet'!I60 -> 163.22 | ... K7: =+'Data Sheet'!K60 -> 243.23
A8: Total Liabilities | B8: =SUM(B4:B7) -> 545.63 | C8: =SUM(C4:C7) -> 552.11 | D8: =SUM(D4:D7) -> 599.19 | E8: =SUM(E4:E7) -> 686.96 | F8: =SUM(F4:F7) -> 821.13 | G8: =SUM(G4:G7) -> 979.95 | H8: =SUM(H4:H7) -> 1227.58 | I8: =SUM(I4:I7) -> 1442.98 | ... K8: =SUM(K4:K7) -> 2089.77
A10: Fixed Assets (Net Block) | B10: =+'Data Sheet'!B62 -> 290.13 | C10: =+'Data Sheet'!C62 -> 304.19 | D10: =+'Data Sheet'!D62 -> 327.25 | E10: =+'Data Sheet'!E62 -> 381.89 | F10: =+'Data Sheet'!F62 -> 467.6 | G10: =+'Data Sheet'!G62 -> 456.84 | H10: =+'Data Sheet'!H62 -> 474.51 | I10: =+'Data Sheet'!I62 -> 750.76 | ... K10: =+'Data Sheet'!K62 -> 873.17
A11: Capital Work in Progress (CWIP) | B11: =+'Data Sheet'!B63 -> 14.05 | C11: =+'Data Sheet'!C63 -> 10.09 | D11: =+'Data Sheet'!D63 -> 20.02 | E11: =+'Data Sheet'!E63 -> 24.83 | F11: =+'Data Sheet'!F63 -> 7.38 | G11: =+'Data Sheet'!G63 -> 34.88 | H11: =+'Data Sheet'!H63 -> 191.18 | I11: =+'Data Sheet'!I63 -> 30.97 | ... K11: =+'Data Sheet'!K63 -> 47.29
A12: Investments | B12: =+'Data Sheet'!B64 -> 12.77 | C12: =+'Data Sheet'!C64 -> 2.74 | D12: =+'Data Sheet'!D64 -> 2.74 | E12: =+'Data Sheet'!E64 -> 2.74 | F12: =+'Data Sheet'!F64 -> 61.83 | G12: =+'Data Sheet'!G64 -> 131.74 | H12: =+'Data Sheet'!H64 -> 96.47 | I12: =+'Data Sheet'!I64 -> 227.39 | ... K12: =+'Data Sheet'!K64 -> 97.88
A13: Other Assets | B13: =+'Data Sheet'!B65 -> 228.68 | C13: =+'Data Sheet'!C65 -> 235.09 | D13: =+'Data Sheet'!D65 -> 249.18 | E13: =+'Data Sheet'!E65 -> 277.5 | F13: =+'Data Sheet'!F65 -> 284.32 | G13: =+'Data Sheet'!G65 -> 356.49 | H13: =+'Data Sheet'!H65 -> 465.42 | I13: =+'Data Sheet'!I65 -> 433.86 | ... K13: =+'Data Sheet'!K65 -> 1071.43
A14: Total Assets | B14: =SUM(B10:B13) -> 545.63 | C14: =SUM(C10:C13) -> 552.11 | D14: =SUM(D10:D13) -> 599.19 | E14: =SUM(E10:E13) -> 686.96 | F14: =SUM(F10:F13) -> 821.13 | G14: =SUM(G10:G13) -> 979.95 | H14: =SUM(H10:H13) -> 1227.58 | I14: =SUM(I10:I13) -> 1442.98 | ... K14: =SUM(K10:K13) -> 2089.77
A16: Receivables | B16: =+'Data Sheet'!B67 -> 113.19 | C16: =+'Data Sheet'!C67 -> 115.05 | D16: =+'Data Sheet'!D67 -> 129.1 | E16: =+'Data Sheet'!E67 -> 114.82 | F16: =+'Data Sheet'!F67 -> 140.54 | G16: =+'Data Sheet'!G67 -> 177.11 | H16: =+'Data Sheet'!H67 -> 243.98 | I16: =+'Data Sheet'!I67 -> 201.78 | ... K16: =+'Data Sheet'!K67 -> 458.38
A17: Inventory | B17: =+'Data Sheet'!B68 -> 54.64 | C17: =+'Data Sheet'!C68 -> 46.63 | D17: =+'Data Sheet'!D68 -> 54.49 | E17: =+'Data Sheet'!E68 -> 44.7 | F17: =+'Data Sheet'!F68 -> 65.07 | G17: =+'Data Sheet'!G68 -> 82.23 | H17: =+'Data Sheet'!H68 -> 92.39 | I17: =+'Data Sheet'!I68 -> 93.17 | ... K17: =+'Data Sheet'!K68 -> 176.16
A18: Cash & Bank | B18: =+'Data Sheet'!B69 -> 33.77 | C18: =+'Data Sheet'!C69 -> 42.7 | D18: =+'Data Sheet'!D69 -> 27.14 | E18: =+'Data Sheet'!E69 -> 72.23 | F18: =+'Data Sheet'!F69 -> 4.75 | G18: =+'Data Sheet'!G69 -> 5.24 | H18: =+'Data Sheet'!H69 -> 3.8 | I18: =+'Data Sheet'!I69 -> 53.7 | ... K18: =+'Data Sheet'!K69 -> 4.28
A19: Working Capital | B19: =B13-B7 -> 161.55 | C19: =C13-C7 -> 154.63 | D19: =D13-D7 -> 149.34 | E19: =E13-E7 -> 173.39 | F19: =F13-F7 -> 145.52 | G19: =G13-G7 -> 188.41 | H19: =H13-H7 -> 292.8 | I19: =I13-I7 -> 270.64 | ... K19: =K13-K7 -> 828.2
A20: Capital Employed | B20: =B4+B5+B6 -> 478.5 | C20: =C4+C5+C6 -> 471.65 | D20: =D4+D5+D6 -> 499.35 | E20: =E4+E5+E6 -> 582.85 | F20: =F4+F5+F6 -> 682.33 | G20: =G4+G5+G6 -> 811.87 | H20: =H4+H5+H6 -> 1054.96 | I20: =I4+I5+I6 -> 1279.76 | ... K20: =K4+K5+K6 -> 1846.54
A21: Total Equity | B21: =B4+B5 -> 241.24 | C21: =C4+C5 -> 310.07 | D21: =D4+D5 -> 434.05 | E21: =E4+E5 -> 540.78 | F21: =F4+F5 -> 680.01 | G21: =G4+G5 -> 796.67 | H21: =H4+H5 -> 1051.28 | I21: =I4+I5 -> 1279.41 | ... K21: =K4+K5 -> 1828.14
A23: Net Fixed Asset Turnover | C23: =IFERROR('Income Statement'!C4/AVERAGE('Balance Sheet'!B10:C10),"n/m") -> 2.34261 | D23: =IFERROR('Income Statement'!D4/AVERAGE('Balance Sheet'!C10:D10),"n/m") -> 2.4443494 | E23: =IFERROR('Income Statement'!E4/AVERAGE('Balance Sheet'!D10:E10),"n/m") -> 1.7794794 | F23: =IFERROR('Income Statement'!F4/AVERAGE('Balance Sheet'!E10:F10),"n/m") -> 1.5086464 | G23: =IFERROR('Income Statement'!G4/AVERAGE('Balance Sheet'!F10:G10),"n/m") -> 1.5786422 | H23: =IFERROR('Income Statement'!H4/AVERAGE('Balance Sheet'!G10:H10),"n/m") -> 2.4221184 | I23: =IFERROR('Income Statement'!I4/AVERAGE('Balance Sheet'!H10:I10),"n/m") -> 1.6794176 | J23: =IFERROR('Income Statement'!J4/AVERAGE('Balance Sheet'!I10:J10),"n/m") -> 1.265941 | K23: =IFERROR('Income Statement'!K4/AVERAGE('Balance Sheet'!J10:K10),"n/m") -> 1.9822209 | M23: =SUM(C23:K23)/M$3 -> 1.8892695 | N23: =SUM(G23:K23)/N$3 -> 1.785668 | O23: =SUM(I23:K23)/O$3 -> 1.6425265
A24: Receivables Days | C24: =IFERROR(365/('Income Statement'!C4/AVERAGE('Balance Sheet'!B16:C16)),"n/m") -> 59.836237 | D24: =IFERROR(365/('Income Statement'!D4/AVERAGE('Balance Sheet'!C16:D16)),"n/m") -> 57.737 | E24: =IFERROR(365/('Income Statement'!E4/AVERAGE('Balance Sheet'!D16:E16)),"n/m") -> 70.552976 | F24: =IFERROR(365/('Income Statement'!F4/AVERAGE('Balance Sheet'!E16:F16)),"n/m") -> 72.727727 | G24: =IFERROR(365/('Income Statement'!G4/AVERAGE('Balance Sheet'!F16:G16)),"n/m") -> 79.447326 | H24: =IFERROR(365/('Income Statement'!H4/AVERAGE('Balance Sheet'!G16:H16)),"n/m") -> 68.133312 | I24: =IFERROR(365/('Income Statement'!I4/AVERAGE('Balance Sheet'!H16:I16)),"n/m") -> 79.068493 | J24: =IFERROR(365/('Income Statement'!J4/AVERAGE('Balance Sheet'!I16:J16)),"n/m") -> 91.596158 | K24: =IFERROR(365/('Income Statement'!K4/AVERAGE('Balance Sheet'!J16:K16)),"n/m") -> 83.092058 | M24: =SUM(C24:K24)/M$3 -> 73.57681 | N24: =SUM(G24:K24)/N$3 -> 80.267469 | O24: =SUM(I24:K24)/O$3 -> 84.58557
A25: Inventory Turnover | C25: =IFERROR(('Income Statement'!C4/AVERAGE('Balance Sheet'!B17:C17)),"n/m") -> 13.748 | D25: =IFERROR(('Income Statement'!D4/AVERAGE('Balance Sheet'!C17:D17)),"n/m") -> 15.263647 | E25: =IFERROR(('Income Statement'!E4/AVERAGE('Balance Sheet'!D17:E17)),"n/m") -> 12.722049 | F25: =IFERROR(('Income Statement'!F4/AVERAGE('Balance Sheet'!E17:F17)),"n/m") -> 11.675139 | G25: =IFERROR(('Income Statement'!G4/AVERAGE('Balance Sheet'!F17:G17)),"n/m") -> 9.9073999 | H25: =IFERROR(('Income Statement'!H4/AVERAGE('Balance Sheet'!G17:H17)),"n/m") -> 12.918566 | I25: =IFERROR(('Income Statement'!I4/AVERAGE('Balance Sheet'!H17:I17)),"n/m") -> 11.089351 | J25: =IFERROR(('Income Statement'!J4/AVERAGE('Balance Sheet'!I17:J17)),"n/m") -> 8.8722979 | K25: =IFERROR(('Income Statement'!K4/AVERAGE('Balance Sheet'!J17:K17)),"n/m") -> 10.838712 | M25: =SUM(C25:K25)/M$3 -> 11.892796 | N25: =SUM(G25:K25)/N$3 -> 10.725265 | O25: =SUM(I25:K25)/O$3 -> 10.266787
A26: Debt To Equity | B26: =+IFERROR(B6/B21,"n/m") -> 0.98350191 | C26: =+IFERROR(C6/C21,"n/m") -> 0.52110814 | D26: =+IFERROR(D6/D21,"n/m") -> 0.1504435 | E26: =+IFERROR(E6/E21,"n/m") -> 0.077795037 | F26: =+IFERROR(F6/F21,"n/m") -> 0.0034117145 | G26: =+IFERROR(G6/G21,"n/m") -> 0.019079418 | H26: =+IFERROR(H6/H21,"n/m") -> 0.0035004946 | I26: =+IFERROR(I6/I21,"n/m") -> 0.0002735636 | ... K26: =+IFERROR(K6/K21,"n/m") -> 0.010064875 | M26: =SUM(C26:K26)/M$3 -> 0.087442835 | N26: =SUM(G26:K26)/N$3 -> 0.0068454266 | O26: =SUM(I26:K26)/O$3 -> 0.0038824067
A27: Return on average Equity (RoAE) | C27: =IFERROR('Income Statement'!C12/AVERAGE('Balance Sheet'!B21:C21),"n/m") -> 0.31256462 | D27: =IFERROR('Income Statement'!D12/AVERAGE('Balance Sheet'!C21:D21),"n/m") -> 0.31124012 | E27: =IFERROR('Income Statement'!E12/AVERAGE('Balance Sheet'!D21:E21),"n/m") -> 0.26993424 | F27: =IFERROR('Income Statement'!F12/AVERAGE('Balance Sheet'!E21:F21),"n/m") -> 0.22980201 | G27: =IFERROR('Income Statement'!G12/AVERAGE('Balance Sheet'!F21:G21),"n/m") -> 0.19486957 | H27: =IFERROR('Income Statement'!H12/AVERAGE('Balance Sheet'!G21:H21),"n/m") -> 0.30573338 | I27: =IFERROR('Income Statement'!I12/AVERAGE('Balance Sheet'!H21:I21),"n/m") -> 0.2864731 | J27: =IFERROR('Income Statement'!J12/AVERAGE('Balance Sheet'!I21:J21),"n/m") -> 0.19083686 | K27: =IFERROR('Income Statement'!K12/AVERAGE('Balance Sheet'!J21:K21),"n/m") -> 0.20564368 | M27: =SUM(C27:K27)/M$3 -> 0.25634418 | N27: =SUM(G27:K27)/N$3 -> 0.23671132 | O27: =SUM(I27:K27)/O$3 -> 0.22765121
A28: Return on average Capital Employed | C28: =IFERROR(('Income Statement'!C10-'Income Statement'!C8)/AVERAGE('Balance Sheet'!B20:C20),"n/m") -> 0.30887755 | D28: =IFERROR(('Income Statement'!D10-'Income Statement'!D8)/AVERAGE('Balance Sheet'!C20:D20),"n/m") -> 0.37746653 | E28: =IFERROR(('Income Statement'!E10-'Income Statement'!E8)/AVERAGE('Balance Sheet'!D20:E20),"n/m") -> 0.35930512 | F28: =IFERROR(('Income Statement'!F10-'Income Statement'!F8)/AVERAGE('Balance Sheet'!E20:F20),"n/m") -> 0.32992934 | G28: =IFERROR(('Income Statement'!G10-'Income Statement'!G8)/AVERAGE('Balance Sheet'!F20:G20),"n/m") -> 0.2751305 | H28: =IFERROR(('Income Statement'!H10-'Income Statement'!H8)/AVERAGE('Balance Sheet'!G20:H20),"n/m") -> 0.45790993 | I28: =IFERROR(('Income Statement'!I10-'Income Statement'!I8)/AVERAGE('Balance Sheet'!H20:I20),"n/m") -> 0.36554276 | J28: =IFERROR(('Income Statement'!J10-'Income Statement'!J8)/AVERAGE('Balance Sheet'!I20:J20),"n/m") -> 0.23800793 | K28: =IFERROR(('Income Statement'!K10-'Income Statement'!K8)/AVERAGE('Balance Sheet'!J20:K20),"n/m") -> 0.2658919 | M28: =SUM(C28:K28)/M$3 -> 0.33089573 | N28: =SUM(G28:K28)/N$3 -> 0.32049661 | O28: =SUM(I28:K28)/O$3 -> 0.2898142
A31: Common Size Balance Sheet
A32: Year >> | B32: =+B3 -> 41364 | C32: =+C3 -> 41729 | D32: =+D3 -> 42094 | E32: =+E3 -> 42460 | F32: =+F3 -> 42825 | G32: =+G3 -> 43190 | H32: =+H3 -> 43555 | I32: =+I3 -> 43921 | ... K32: =+K3 -> 44651
A33: Equity Share Capital | B33: =B4/B$8 -> 0.018089181 | C33: =C4/C$8 -> 0.017876872 | D33: =D4/D$8 -> 0.017223251 | E33: =E4/E$8 -> 0.015022709 | F33: =F4/F$8 -> 0.012568046 | G33: =G4/G$8 -> 0.010490331 | H33: =H4/H$8 -> 0.0083741996 | I33: =I4/I$8 -> 0.0071241459 | ... K33: =K4/K$8 -> 0.0049192016
A34: Reserves | B34: =B5/B$8 -> 0.42404193 | C34: =C5/C$8 -> 0.54373223 | D34: =D5/D$8 -> 0.70717135 | E34: =E5/E$8 -> 0.7721847 | F34: =F5/F$8 -> 0.81557123 | G34: =G5/G$8 -> 0.80247972 | H34: =H5/H$8 -> 0.84800991 | I34: =I5/I$8 -> 0.87952016 | ... K34: =K5/K$8 -> 0.8698852
A35: Borrowings | B35: =B6/B$8 -> 0.43483679 | C35: =C6/C$8 -> 0.29265907 | D35: =D6/D$8 -> 0.10898046 | E35: =E6/E$8 -> 0.061240829 | F35: =F6/F$8 -> 0.0028253748 | G35: =G6/G$8 -> 0.015510995 | H35: =H6/H$8 -> 0.002997768 | I35: =I6/I$8 -> 0.0002425536 | ... K35: =K6/K$8 -> 0.0088047967
A36: Other Liabilities | B36: =B7/B$8 -> 0.12303209 | C36: =C7/C$8 -> 0.14573183 | D36: =D7/D$8 -> 0.16662494 | E36: =E7/E$8 -> 0.15155176 | F36: =F7/F$8 -> 0.16903535 | G36: =G7/G$8 -> 0.17151896 | H36: =H7/H$8 -> 0.14061813 | I36: =I7/I$8 -> 0.11311314 | ... K36: =K7/K$8 -> 0.1163908
A37: Total Liabilities | B37: =B8/B$8 -> 1 | C37: =C8/C$8 -> 1 | D37: =D8/D$8 -> 1 | E37: =E8/E$8 -> 1 | F37: =F8/F$8 -> 1 | G37: =G8/G$8 -> 1 | H37: =H8/H$8 -> 1 | I37: =I8/I$8 -> 1 | ... K37: =K8/K$8 -> 1
A39: Fixed Assets (Net Block) | B39: =B10/B$14 -> 0.53173396 | C39: =C10/C$14 -> 0.55095905 | D39: =D10/D$14 -> 0.54615397 | E39: =E10/E$14 -> 0.55591301 | F39: =F10/F$14 -> 0.56945916 | G39: =G10/G$14 -> 0.46618705 | H39: =H10/H$14 -> 0.386541 | I39: =I10/I$14 -> 0.52028441 | ... K39: =K10/K$14 -> 0.41783067
A40: Capital Work in Progress (CWIP) | B40: =B11/B$14 -> 0.02575005 | C40: =C11/C$14 -> 0.018275344 | D40: =D11/D$14 -> 0.033411773 | E40: =E11/E$14 -> 0.036144754 | F40: =F11/F$14 -> 0.0089876146 | G40: =G11/G$14 -> 0.035593653 | H40: =H11/H$14 -> 0.1557373 | I40: =I11/I$14 -> 0.021462529 | ... K40: =K11/K$14 -> 0.022629285
A41: Investments | B41: =B12/B$14 -> 0.023404138 | C41: =C12/C$14 -> 0.0049627792 | D41: =D12/D$14 -> 0.00457284 | E41: =E12/E$14 -> 0.0039885874 | F41: =F12/F$14 -> 0.075298674 | G41: =G12/G$14 -> 0.13443543 | H41: =H12/H$14 -> 0.07858551 | I41: =I12/I$14 -> 0.15758361 | ... K41: =K12/K$14 -> 0.04683769
A42: Other Assets | B42: =B13/B$14 -> 0.41911185 | C42: =C13/C$14 -> 0.42580283 | D42: =D13/D$14 -> 0.41586141 | E42: =E13/E$14 -> 0.40395365 | F42: =F13/F$14 -> 0.34625455 | G42: =G13/G$14 -> 0.36378387 | H42: =H13/H$14 -> 0.37913619 | I42: =I13/I$14 -> 0.30066945 | ... K42: =K13/K$14 -> 0.51270235
A43: Total Assets | B43: =B14/B$14 -> 1 | C43: =C14/C$14 -> 1 | D43: =D14/D$14 -> 1 | E43: =E14/E$14 -> 1 | F43: =F14/F$14 -> 1 | G43: =G14/G$14 -> 1 | H43: =H14/H$14 -> 1 | I43: =I14/I$14 -> 1 | ... K43: =K14/K$14 -> 1
A45: Other items as % of Total Assets
A46: Receivables | B46: =B16/B$14 -> 0.20744827 | C46: =C16/C$14 -> 0.20838239 | D46: =D16/D$14 -> 0.21545753 | E46: =E16/E$14 -> 0.16714219 | F46: =F16/F$14 -> 0.17115438 | G46: =G16/G$14 -> 0.18073371 | H46: =H16/H$14 -> 0.19874876 | I46: =I16/I$14 -> 0.13983562 | ... K46: =K16/K$14 -> 0.21934471
A47: Inventory | B47: =B17/B$14 -> 0.10014112 | C47: =C17/C$14 -> 0.084457807 | D47: =D17/D$14 -> 0.090939435 | E47: =E17/E$14 -> 0.065069291 | F47: =F17/F$14 -> 0.079244456 | G47: =G17/G$14 -> 0.083912445 | H47: =H17/H$14 -> 0.075261897 | I47: =I17/I$14 -> 0.064567769 | ... K47: =K17/K$14 -> 0.084296358
...

Sheet Cashflow Statement
A1: Cashflow Analysis
A2: COMPANY NAME >> | B2: =+'Data Sheet'!B1 -> VINATI ORGANICS LTD | M2: GROWTH TREND ANALYSIS
A3: INR (in crores) | B3: =+'Data Sheet'!B16 -> 41364 | C3: =+'Data Sheet'!C16 -> 41729 | D3: =+'Data Sheet'!D16 -> 42094 | E3: =+'Data Sheet'!E16 -> 42460 | F3: =+'Data Sheet'!F16 -> 42825 | G3: =+'Data Sheet'!G16 -> 43190 | H3: =+'Data Sheet'!H16 -> 43555 | I3: =+'Data Sheet'!I16 -> 43921 | ... K3: =+'Data Sheet'!K16 -> 44651 | L3: TOTAL | M3: 9 | N3: 5 | O3: 3
A4: Cash from Operating Activity (CFO) | B4: =+'Data Sheet'!B82 -> 92.1 | C4: =+'Data Sheet'!C82 -> 131.46 | D4: =+'Data Sheet'!D82 -> 112.56 | E4: =+'Data Sheet'!E82 -> 167.49 | F4: =+'Data Sheet'!F82 -> 130.43 | G4: =+'Data Sheet'!G82 -> 138.33 | H4: =+'Data Sheet'!H82 -> 200.36 | I4: =+'Data Sheet'!I82 -> 415.93 | ... K4: =+'Data Sheet'!K82 -> 127.1
A5: Cash from Investing Activity (CFI) | B5: =+'Data Sheet'!B83 -> -112.58 | C5: =+'Data Sheet'!C83 -> -9.04 | D5: =+'Data Sheet'!D83 -> -53.49 | E5: =+'Data Sheet'!E83 -> -72.19 | F5: =+'Data Sheet'!F83 -> -26.79 | G5: =+'Data Sheet'!G83 -> -38.78 | H5: =+'Data Sheet'!H83 -> -242.71 | I5: =+'Data Sheet'!I83 -> -197.46 | ... K5: =+'Data Sheet'!K83 -> -255.8
A6: Cash from Financing Activity (CFF) | B6: =+'Data Sheet'!B84 -> 22.3 | C6: =+'Data Sheet'!C84 -> -113.49 | D6: =+'Data Sheet'!D84 -> -74.63 | E6: =+'Data Sheet'!E84 -> -50.22 | F6: =+'Data Sheet'!F84 -> -45.08 | G6: =+'Data Sheet'!G84 -> -29.86 | H6: =+'Data Sheet'!H84 -> -40.26 | I6: =+'Data Sheet'!I84 -> -109.05 | ... K6: =+'Data Sheet'!K84 -> -46.43
A7: Net Cash Flow (CFO + CFI + CFF) | B7: =SUM(B4:B6) -> 1.82 | C7: =SUM(C4:C6) -> 8.93 | D7: =SUM(D4:D6) -> -15.56 | E7: =SUM(E4:E6) -> 45.08 | F7: =SUM(F4:F6) -> 58.56 | G7: =SUM(G4:G6) -> 69.69 | H7: =SUM(H4:H6) -> -82.61 | I7: =SUM(I4:I6) -> 109.42 | ... K7: =SUM(K4:K6) -> -175.13
A9: Cash & Equivalent at the end of year | B9: ='Balance Sheet'!B18 -> 33.77 | C9: ='Balance Sheet'!C18 -> 42.7 | D9: ='Balance Sheet'!D18 -> 27.14 | E9: ='Balance Sheet'!E18 -> 72.23 | F9: ='Balance Sheet'!F18 -> 4.75 | G9: ='Balance Sheet'!G18 -> 5.24 | H9: ='Balance Sheet'!H18 -> 3.8 | I9: ='Balance Sheet'!I18 -> 53.7 | ... K9: ='Balance Sheet'!K18 -> 4.28
A11: Profit After Tax (PAT) | B11: =+'Income Statement'!B12 -> 68.67 | C11: =+'Income Statement'!C12 -> 86.16 | D11: =+'Income Statement'!D12 -> 115.8 | E11: =+'Income Statement'!E12 -> 131.57 | F11: =+'Income Statement'!F12 -> 140.27 | G11: =+'Income Statement'!G12 -> 143.88 | H11: =+'Income Statement'!H12 -> 282.49 | I11: =+'Income Statement'!I12 -> 333.84 | ... K11: =+'Income Statement'!K12 -> 346.67 | L11: =SUM(B11:K11) -> 1918.7 | M11: =IFERROR((K11/B11)^(1/$M$3)-1,"n/m") -> 0.19709245 | N11: =IFERROR((K11/F11)^(1/$N$3)-1,"n/m") -> 0.19836825 | O11: =IFERROR((K11/H11)^(1/$O$3)-1,"n/m") -> 0.070625855
A12: Cash from Operating Activity (CFO) | B12: =+B4 -> 92.1 | C12: =+C4 -> 131.46 | D12: =+D4 -> 112.56 | E12: =+E4 -> 167.49 | F12: =+F4 -> 130.43 | G12: =+G4 -> 138.33 | H12: =+H4 -> 200.36 | I12: =+I4 -> 415.93 | ... K12: =+K4 -> 127.1 | L12: =SUM(B12:K12) -> 1734.67 | M12: =IFERROR((K12/B12)^(1/$M$3)-1,"n/m") -> 0.036436932 | N12: =IFERROR((K12/F12)^(1/$N$3)-1,"n/m") -> -0.0051591469 | O12: =IFERROR((K12/H12)^(1/$O$3)-1,"n/m") -> -0.14076589
A14: CFO/PAT (atleast 80%) | B14: =IFERROR(B12/B11,"n/m") -> 1.341197 | C14: =IFERROR(C12/C11,"n/m") -> 1.525766 | D14: =IFERROR(D12/D11,"n/m") -> 0.97202073 | E14: =IFERROR(E12/E11,"n/m") -> 1.2730106 | F14: =IFERROR(F12/F11,"n/m") -> 0.92984958 | G14: =IFERROR(G12/G11,"n/m") -> 0.96142619 | H14: =IFERROR(H12/H11,"n/m") -> 0.70926404 | I14: =IFERROR(I12/I11,"n/m") -> 1.2458962 | ... K14: =IFERROR(K12/K11,"n/m") -> 0.36663109 | L14: =L12/L11 -> 0.9040861
A16: CAPEX | C16: =('Balance Sheet'!C10-'Balance Sheet'!B10)+('Balance Sheet'!C11-'Balance Sheet'!B11)-'Income Statement'!C9 -> 25.42 | D16: =('Balance Sheet'!D10-'Balance Sheet'!C10)+('Balance Sheet'!D11-'Balance Sheet'!C11)-'Income Statement'!D9 -> 50.65 | E16: =('Balance Sheet'!E10-'Balance Sheet'!D10)+('Balance Sheet'!E11-'Balance Sheet'!D11)-'Income Statement'!E9 -> 77.97 | F16: =('Balance Sheet'!F10-'Balance Sheet'!E10)+('Balance Sheet'!F11-'Balance Sheet'!E11)-'Income Statement'!F9 -> 89.87 | G16: =('Balance Sheet'!G10-'Balance Sheet'!F10)+('Balance Sheet'!G11-'Balance Sheet'!F11)-'Income Statement'!G9 -> 40.1 | H16: =('Balance Sheet'!H10-'Balance Sheet'!G10)+('Balance Sheet'!H11-'Balance Sheet'!G11)-'Income Statement'!H9 -> 201.36 | I16: =('Balance Sheet'!I10-'Balance Sheet'!H10)+('Balance Sheet'!I11-'Balance Sheet'!H11)-'Income Statement'!I9 -> 149.2 | J16: =('Balance Sheet'!J10-'Balance Sheet'!I10)+('Balance Sheet'!J11-'Balance Sheet'!I11)-'Income Statement'!J9 -> 72.7 | K16: =('Balance Sheet'!K10-'Balance Sheet'!J10)+('Balance Sheet'!K11-'Balance Sheet'!J11)-'Income Statement'!K9 -> 154.43
A17: Free Cash Flows (FCF) | C17: =C12-C16 -> 106.04 | D17: =D12-D16 -> 61.91 | E17: =E12-E16 -> 89.52 | F17: =F12-F16 -> 40.56 | G17: =G12-G16 -> 98.23 | H17: =H12-H16 -> -1 | I17: =I12-I16 -> 266.73 | J17: =J12-J16 -> 146.21 | K17: =K12-K16 -> -27.33
A19: Re-investment (Capex/CFO) | C19: =IFERROR(C16/C4,"n/m") -> 0.1933668 | D19: =IFERROR(D16/D4,"n/m") -> 0.44998223 | E19: =IFERROR(E16/E4,"n/m") -> 0.46552033 | F19: =IFERROR(F16/F4,"n/m") -> 0.6890286 | G19: =IFERROR(G16/G4,"n/m") -> 0.2898865 | H19: =IFERROR(H16/H4,"n/m") -> 1.004991 | I19: =IFERROR(I16/I4,"n/m") -> 0.35871421 | J19: =IFERROR(J16/J4,"n/m") -> 0.33209995 | K19: =IFERROR(K16/K4,"n/m") -> 1.2150275
A20: FCF/CFO | L20: =SUM(C17:K17)/SUM(C12:K12) -> 0.47539526

Sheet Ratio Analysis
A1: Ratio Analysis
A2: COMPANY NAME >> | B2: =+'Data Sheet'!B1 -> VINATI ORGANICS LTD
A3: INR (in crores) | B3: =+'Data Sheet'!B16 -> 41364 | C3: =+'Data Sheet'!C16 -> 41729 | D3: =+'Data Sheet'!D16 -> 42094 | E3: =+'Data Sheet'!E16 -> 42460 | F3: =+'Data Sheet'!F16 -> 42825 | G3: =+'Data Sheet'!G16 -> 43190 | H3: =+'Data Sheet'!H16 -> 43555 | I3: =+'Data Sheet'!I16 -> 43921 | ... K3: =+'Data Sheet'!K16 -> 44651 | L3: TTM
A4: Operating Profit Margin (OPM) % | B4: =+'Income Statement'!B23 -> 0.2171144 | C4: =+'Income Statement'!C23 -> 0.21962852 | D4: =+'Income Statement'!D23 -> 0.24892125 | E4: =+'Income Statement'!E23 -> 0.32783897 | F4: =+'Income Statement'!F23 -> 0.33995537 | G4: =+'Income Statement'!G23 -> 0.27174926 | H4: =+'Income Statement'!H23 -> 0.37680864 | I4: =+'Income Statement'!I23 -> 0.40324822 | ... L4: =+'Income Statement'!L23 -> 0.26503774
A5: Net Profit Margin (NPM) % | B5: =+'Income Statement'!B24 -> 0.12389269 | C5: =+'Income Statement'!C24 -> 0.12376999 | D5: =+'Income Statement'!D24 -> 0.15005248 | E5: =+'Income Statement'!E24 -> 0.20852682 | F5: =+'Income Statement'!F24 -> 0.21890167 | G5: =+'Income Statement'!G24 -> 0.19718233 | H5: =+'Income Statement'!H24 -> 0.25045216 | I5: =+'Income Statement'!I24 -> 0.32447248 | ... L5: =+'Income Statement'!L24 -> 0.20832101
A6: Tax Payout % | B6: =+'Income Statement'!B25 -> 0.33076698 | C6: =+'Income Statement'!C25 -> 0.32996345 | D6: =+'Income Statement'!D25 -> 0.33256484 | E6: =+'Income Statement'!E25 -> 0.29475772 | F6: =+'Income Statement'!F25 -> 0.31894543 | G6: =+'Income Statement'!G25 -> 0.29255581 | H6: =+'Income Statement'!H25 -> 0.33569279 | I6: =+'Income Statement'!I25 -> 0.21390223 | ... K6: =+'Income Statement'!K25 -> 0.22842199
A7: Dividend Payout % | B7: =+'Income Statement'!B26 -> 0.17972619 | C7: =+'Income Statement'!C26 -> 0.17179338 | D7: =+'Income Statement'!D26 -> 0.15597202 | E7: =+'Income Statement'!E26 -> 0.15687467 | F7: =+'Income Statement'!F26 -> 0.018391788 | G7: =+'Income Statement'!G26 -> 0.16075897 | H7: =+'Income Statement'!H26 -> 0.12736734 | I7: =+'Income Statement'!I26 -> 0.16936764 | ... K7: =+'Income Statement'!K26 -> 0.19274259
A8: Interest Coverage Ratio (x) | B8: =+'Income Statement'!B27 -> 9.8916811 | C8: =+'Income Statement'!C27 -> 8.0848485 | D8: =+'Income Statement'!D27 -> 18.776639 | E8: =+'Income Statement'!E27 -> 24.735369 | F8: =+'Income Statement'!F27 -> 75.894545 | G8: =+'Income Statement'!G27 -> 94.723502 | H8: =+'Income Statement'!H27 -> 196.06422 | I8: =+'Income Statement'!I27 -> 209.17647 | ... K8: =+'Income Statement'!K27 -> 273.30303
A9: Earnings Per Share (EPS) | B9: =+'Income Statement'!B28 -> 6.9715736 | C9: =+'Income Statement'!C28 -> 8.7472081 | D9: =+'Income Statement'!D28 -> 11.22093 | E9: =+'Income Statement'!E28 -> 12.749031 | F9: =+'Income Statement'!F28 -> 13.592054 | G9: =+'Income Statement'!G28 -> 13.996109 | H9: =+'Income Statement'!H28 -> 27.479572 | I9: =+'Income Statement'!I28 -> 32.474708 | ... K9: =+'Income Statement'!K28 -> 33.722763
A10: PE Ratio (x) | B10: =+'Income Statement'!B29 -> 7.4416485 | C10: =+'Income Statement'!C29 -> 16.065698 | D10: =+'Income Statement'!D29 -> 23.344767 | E10: =+'Income Statement'!E29 -> 15.258415 | F10: =+'Income Statement'!F29 -> 27.883938 | G10: =+'Income Statement'!G29 -> 32.243247 | H10: =+'Income Statement'!H29 -> 29.91968 | I10: =+'Income Statement'!I29 -> 23.850869 | ... K10: =+'Income Statement'!K29 -> 57.919335
A12: Net Fixed Asset Turnover | C12: =+'Balance Sheet'!C23 -> 2.34261 | D12: =+'Balance Sheet'!D23 -> 2.4443494 | E12: =+'Balance Sheet'!E23 -> 1.7794794 | F12: =+'Balance Sheet'!F23 -> 1.5086464 | G12: =+'Balance Sheet'!G23 -> 1.5786422 | H12: =+'Balance Sheet'!H23 -> 2.4221184 | I12: =+'Balance Sheet'!I23 -> 1.6794176 | J12: =+'Balance Sheet'!J23 -> 1.265941 | K12: =+'Balance Sheet'!K23 -> 1.9822209
A13: Receivables Days | C13: =+'Balance Sheet'!C24 -> 59.836237 | D13: =+'Balance Sheet'!D24 -> 57.737 | E13: =+'Balance Sheet'!E24 -> 70.552976 | F13: =+'Balance Sheet'!F24 -> 72.727727 | G13: =+'Balance Sheet'!G24 -> 79.447326 | H13: =+'Balance Sheet'!H24 -> 68.133312 | I13: =+'Balance Sheet'!I24 -> 79.068493 | J13: =+'Balance Sheet'!J24 -> 91.596158 | K13: =+'Balance Sheet'!K24 -> 83.092058
A14: Inventory Turnover | C14: =+'Balance Sheet'!C25 -> 13.748 | D14: =+'Balance Sheet'!D25 -> 15.263647 | E14: =+'Balance Sheet'!E25 -> 12.722049 | F14: =+'Balance Sheet'!F25 -> 11.675139 | G14: =+'Balance Sheet'!G25 -> 9.9073999 | H14: =+'Balance Sheet'!H25 -> 12.918566 | I14: =+'Balance Sheet'!I25 -> 11.089351 | J14: =+'Balance Sheet'!J25 -> 8.8722979 | K14: =+'Balance Sheet'!K25 -> 10.838712
A15: Debt To Equity | B15: =+'Balance Sheet'!B26 -> 0.98350191 | C15: =+'Balance Sheet'!C26 -> 0.52110814 | D15: =+'Balance Sheet'!D26 -> 0.1504435 | E15: =+'Balance Sheet'!E26 -> 0.077795037 | F15: =+'Balance Sheet'!F26 -> 0.0034117145 | G15: =+'Balance Sheet'!G26 -> 0.019079418 | H15: =+'Balance Sheet'!H26 -> 0.0035004946 | I15: =+'Balance Sheet'!I26 -> 0.0002735636 | ... K15: =+'Balance Sheet'!K26 -> 0.010064875
A16: Return on average Equity (RoAE) | C16: =+'Balance Sheet'!C27 -> 0.31256462 | D16: =+'Balance Sheet'!D27 -> 0.31124012 | E16: =+'Balance Sheet'!E27 -> 0.26993424 | F16: =+'Balance Sheet'!F27 -> 0.22980201 | G16: =+'Balance Sheet'!G27 -> 0.19486957 | H16: =+'Balance Sheet'!H27 -> 0.30573338 | I16: =+'Balance Sheet'!I27 -> 0.2864731 | J16: =+'Balance Sheet'!J27 -> 0.19083686 | K16: =+'Balance Sheet'!K27 -> 0.20564368
A17: Return on average Capital Employed | C17: =+'Balance Sheet'!C28 -> 0.30887755 | D17: =+'Balance Sheet'!D28 -> 0.37746653 | E17: =+'Balance Sheet'!E28 -> 0.35930512 | F17: =+'Balance Sheet'!F28 -> 0.32992934 | G17: =+'Balance Sheet'!G28 -> 0.2751305 | H17: =+'Balance Sheet'!H28 -> 0.45790993 | I17: =+'Balance Sheet'!I28 -> 0.36554276 | J17: =+'Balance Sheet'!J28 -> 0.23800793 | K17: =+'Balance Sheet'!K28 -> 0.2658919
A19: CFO/PAT (atleast 80%) | B19: =+'Cashflow Statement'!B14 -> 1.341197 | C19: =+'Cashflow Statement'!C14 -> 1.525766 | D19: =+'Cashflow Statement'!D14 -> 0.97202073 | E19: =+'Cashflow Statement'!E14 -> 1.2730106 | F19: =+'Cashflow Statement'!F14 -> 0.92984958 | G19: =+'Cashflow Statement'!G14 -> 0.96142619 | H19: =+'Cashflow Statement'!H14 -> 0.70926404 | I19: =+'Cashflow Statement'!I14 -> 1.2458962 | ... K19: =+'Cashflow Statement'!K14 -> 0.36663109
A21: FIVE STAGE MODEL - DUPONT ANALYSIS
A22: Tax Burden (Net Income ÷ PBT) | B22: =+'DuPont Analysis'!B20 -> 0.66923302 | C22: =+'DuPont Analysis'!C20 -> 0.67003655 | D22: =+'DuPont Analysis'!D20 -> 0.66743516 | E22: =+'DuPont Analysis'!E20 -> 0.70524228 | F22: =+'DuPont Analysis'!F20 -> 0.68105457 | G22: =+'DuPont Analysis'!G20 -> 0.70744419 | H22: =+'DuPont Analysis'!H20 -> 0.66430721 | I22: =+'DuPont Analysis'!I20 -> 0.78609777 | ... K22: =+'DuPont Analysis'!K20 -> 0.77157801
A23: Interest Burden (PBT ÷ EBIT) | B23: =+'DuPont Analysis'!B21 -> 0.89890495 | C23: =+'DuPont Analysis'!C21 -> 0.87631184 | D23: =+'DuPont Analysis'!D21 -> 0.94674233 | E23: =+'DuPont Analysis'!E21 -> 0.95957206 | F23: =+'DuPont Analysis'!F21 -> 0.98682382 | G23: =+'DuPont Analysis'!G21 -> 0.98944296 | H23: =+'DuPont Analysis'!H21 -> 0.99489963 | I23: =+'DuPont Analysis'!I21 -> 0.99521935 | ... K23: =+'DuPont Analysis'!K21 -> 0.99634106
A24: EBIT Margin (EBIT ÷ Sales) | B24: =+'DuPont Analysis'!B22 -> 0.20594656 | C24: =+'DuPont Analysis'!C22 -> 0.21079396 | D24: =+'DuPont Analysis'!D22 -> 0.23746647 | E24: =+'DuPont Analysis'!E22 -> 0.30813852 | F24: =+'DuPont Analysis'!F22 -> 0.32570733 | G24: =+'DuPont Analysis'!G22 -> 0.28169883 | H24: =+'DuPont Analysis'!H22 -> 0.37894532 | I24: =+'DuPont Analysis'!I22 -> 0.41474628 | ... K24: =+'DuPont Analysis'!K22 -> 0.27913786
A25: Asset Turnover (Sales ÷ Total Assets) | B25: =+'DuPont Analysis'!B23 -> 1.0158349 | C25: =+'DuPont Analysis'!C23 -> 1.2608538 | D25: =+'DuPont Analysis'!D23 -> 1.2879554 | E25: =+'DuPont Analysis'!E23 -> 0.91846687 | F25: =+'DuPont Analysis'!F23 -> 0.78037582 | G25: =+'DuPont Analysis'!G23 -> 0.74460942 | H25: =+'DuPont Analysis'!H23 -> 0.91881588 | I25: =+'DuPont Analysis'!I23 -> 0.71301751 | ... K25: =+'DuPont Analysis'!K23 -> 0.77305637
A26: Equity Multiplier (Total Assets ÷ Shareholders Equity) | B26: =+'DuPont Analysis'!B24 -> 2.2617725 | C26: =+'DuPont Analysis'!C24 -> 1.7805979 | D26: =+'DuPont Analysis'!D24 -> 1.3804631 | E26: =+'DuPont Analysis'!E24 -> 1.2703133 | F26: =+'DuPont Analysis'!F24 -> 1.2075264 | G26: =+'DuPont Analysis'!G24 -> 1.2300576 | H26: =+'DuPont Analysis'!H24 -> 1.1677003 | I26: =+'DuPont Analysis'!I24 -> 1.127848 | ... K26: =+'DuPont Analysis'!K24 -> 1.1431127
A27: Return on Equity | B27: =+'DuPont Analysis'!B25 -> 0.28465429 | C27: =+'DuPont Analysis'!C25 -> 0.27787274 | D27: =+'DuPont Analysis'!D25 -> 0.26678954 | E27: =+'DuPont Analysis'!E25 -> 0.24329672 | F27: =+'DuPont Analysis'!F25 -> 0.20627638 | G27: =+'DuPont Analysis'!G25 -> 0.18060175 | H27: =+'DuPont Analysis'!H25 -> 0.26871052 | I27: =+'DuPont Analysis'!I25 -> 0.26093277 | ... K27: =+'DuPont Analysis'!K25 -> 0.1896299

Sheet DuPont Analysis
A1: DuPont Analysis
A2: COMPANY NAME >> | B2: =+'Data Sheet'!B1 -> VINATI ORGANICS LTD
A3: INR (in crores) | B3: =+'Data Sheet'!B16 -> 41364 | C3: =+'Data Sheet'!C16 -> 41729 | D3: =+'Data Sheet'!D16 -> 42094 | E3: =+'Data Sheet'!E16 -> 42460 | F3: =+'Data Sheet'!F16 -> 42825 | G3: =+'Data Sheet'!G16 -> 43190 | H3: =+'Data Sheet'!H16 -> 43555 | I3: =+'Data Sheet'!I16 -> 43921 | ... K3: =+'Data Sheet'!K16 -> 44651
A4: Sales | B4: =+'Income Statement'!B4 -> 554.27 | C4: =+'Income Statement'!C4 -> 696.13 | D4: =+'Income Statement'!D4 -> 771.73 | E4: =+'Income Statement'!E4 -> 630.95 | F4: =+'Income Statement'!F4 -> 640.79 | G4: =+'Income Statement'!G4 -> 729.68 | H4: =+'Income Statement'!H4 -> 1127.92 | I4: =+'Income Statement'!I4 -> 1028.87 | ... K4: =+'Income Statement'!K4 -> 1615.51
A5: Profit before tax (PBT) | B5: =+'Income Statement'!B10 -> 102.61 | C5: =+'Income Statement'!C10 -> 128.59 | D5: =+'Income Statement'!D10 -> 173.5 | E5: =+'Income Statement'!E10 -> 186.56 | F5: =+'Income Statement'!F10 -> 205.96 | G5: =+'Income Statement'!G10 -> 203.38 | H5: =+'Income Statement'!H10 -> 425.24 | I5: =+'Income Statement'!I10 -> 424.68 | ... K5: =+'Income Statement'!K10 -> 449.3
A6: EBIT (Operating Profit + Other Income - Depreciation) | B6: =+'Income Statement'!B5+'Income Statement'!B6+'Income Statement'!B9 -> 114.15 | C6: =+'Income Statement'!C5+'Income Statement'!C6+'Income Statement'!C9 -> 146.74 | D6: =+'Income Statement'!D5+'Income Statement'!D6+'Income Statement'!D9 -> 183.26 | E6: =+'Income Statement'!E5+'Income Statement'!E6+'Income Statement'!E9 -> 194.42 | F6: =+'Income Statement'!F5+'Income Statement'!F6+'Income Statement'!F9 -> 208.71 | G6: =+'Income Statement'!G5+'Income Statement'!G6+'Income Statement'!G9 -> 205.55 | H6: =+'Income Statement'!H5+'Income Statement'!H6+'Income Statement'!H9 -> 427.42 | I6: =+'Income Statement'!I5+'Income Statement'!I6+'Income Statement'!I9 -> 426.72 | ... K6: =+'Income Statement'!K5+'Income Statement'!K6+'Income Statement'!K9 -> 450.95
A7: Interest Expense | B7: ='Income Statement'!B8 -> -11.54 | C7: ='Income Statement'!C8 -> -18.15 | D7: ='Income Statement'!D8 -> -9.76 | E7: ='Income Statement'!E8 -> -7.86 | F7: ='Income Statement'!F8 -> -2.75 | G7: ='Income Statement'!G8 -> -2.17 | H7: ='Income Statement'!H8 -> -2.18 | I7: ='Income Statement'!I8 -> -2.04 | ... K7: ='Income Statement'!K8 -> -1.65
A8: Income Tax | B8: ='Income Statement'!B11 -> -33.94 | C8: ='Income Statement'!C11 -> -42.43 | D8: ='Income Statement'!D11 -> -57.7 | E8: ='Income Statement'!E11 -> -54.99 | F8: ='Income Statement'!F11 -> -65.69 | G8: ='Income Statement'!G11 -> -59.5 | H8: ='Income Statement'!H11 -> -142.75 | I8: ='Income Statement'!I11 -> -90.84 | ... K8: ='Income Statement'!K11 -> -102.63
A9: Net Income | B9: =+'Income Statement'!B12 -> 68.67 | C9: =+'Income Statement'!C12 -> 86.16 | D9: =+'Income Statement'!D12 -> 115.8 | E9: =+'Income Statement'!E12 -> 131.57 | F9: =+'Income Statement'!F12 -> 140.27 | G9: =+'Income Statement'!G12 -> 143.88 | H9: =+'Income Statement'!H12 -> 282.49 | I9: =+'Income Statement'!I12 -> 333.84 | ... K9: =+'Income Statement'!K12 -> 346.67
A10: Total Assets | B10: ='Balance Sheet'!B14 -> 545.63 | C10: ='Balance Sheet'!C14 -> 552.11 | D10: ='Balance Sheet'!D14 -> 599.19 | E10: ='Balance Sheet'!E14 -> 686.96 | F10: ='Balance Sheet'!F14 -> 821.13 | G10: ='Balance Sheet'!G14 -> 979.95 | H10: ='Balance Sheet'!H14 -> 1227.58 | I10: ='Balance Sheet'!I14 -> 1442.98 | ... K10: ='Balance Sheet'!K14 -> 2089.77
A11: Shareholders Equity | B11: ='Balance Sheet'!B21 -> 241.24 | C11: ='Balance Sheet'!C21 -> 310.07 | D11: ='Balance Sheet'!D21 -> 434.05 | E11: ='Balance Sheet'!E21 -> 540.78 | F11: ='Balance Sheet'!F21 -> 680.01 | G11: ='Balance Sheet'!G21 -> 796.67 | H11: ='Balance Sheet'!H21 -> 1051.28 | I11: ='Balance Sheet'!I21 -> 1279.41 | ... K11: ='Balance Sheet'!K21 -> 1828.14
A13: THREE STAGE MODEL
A14: Net Profit Margin (Net Income ÷ Sales) | B14: =+IFERROR(B9/B4,"n/m") -> 0.12389269 | C14: =+IFERROR(C9/C4,"n/m") -> 0.12376999 | D14: =+IFERROR(D9/D4,"n/m") -> 0.15005248 | E14: =+IFERROR(E9/E4,"n/m") -> 0.20852682 | F14: =+IFERROR(F9/F4,"n/m") -> 0.21890167 | G14: =+IFERROR(G9/G4,"n/m") -> 0.19718233 | H14: =+IFERROR(H9/H4,"n/m") -> 0.25045216 | I14: =+IFERROR(I9/I4,"n/m") -> 0.32447248 | ... K14: =+IFERROR(K9/K4,"n/m") -> 0.21458858
A15: Asset Turnover (Sales ÷ Total Assets) | B15: =IFERROR(B4/B10,"n/m") -> 1.0158349 | C15: =IFERROR(C4/C10,"n/m") -> 1.2608538 | D15: =IFERROR(D4/D10,"n/m") -> 1.2879554 | E15: =IFERROR(E4/E10,"n/m") -> 0.91846687 | F15: =IFERROR(F4/F10,"n/m") -> 0.78037582 | G15: =IFERROR(G4/G10,"n/m") -> 0.74460942 | H15: =IFERROR(H4/H10,"n/m") -> 0.91881588 | I15: =IFERROR(I4/I10,"n/m") -> 0.71301751 | ... K15: =IFERROR(K4/K10,"n/m") -> 0.77305637
A16: Equity Multiplier (Total Assets ÷ Shareholders Equity) | B16: =IFERROR(B10/B11,"n/m") -> 2.2617725 | C16: =IFERROR(C10/C11,"n/m") -> 1.7805979 | D16: =IFERROR(D10/D11,"n/m") -> 1.3804631 | E16: =IFERROR(E10/E11,"n/m") -> 1.2703133 | F16: =IFERROR(F10/F11,"n/m") -> 1.2075264 | G16: =IFERROR(G10/G11,"n/m") -> 1.2300576 | H16: =IFERROR(H10/H11,"n/m") -> 1.1677003 | I16: =IFERROR(I10/I11,"n/m") -> 1.127848 | ... K16: =IFERROR(K10/K11,"n/m") -> 1.1431127
A17: Return on Equity | B17: =IFERROR(B14*B15*B16,"n/m") -> 0.28465429 | C17: =IFERROR(C14*C15*C16,"n/m") -> 0.27787274 | D17: =IFERROR(D14*D15*D16,"n/m") -> 0.26678954 | E17: =IFERROR(E14*E15*E16,"n/m") -> 0.24329672 | F17: =IFERROR(F14*F15*F16,"n/m") -> 0.20627638 | G17: =IFERROR(G14*G15*G16,"n/m") -> 0.18060175 | H17: =IFERROR(H14*H15*H16,"n/m") -> 0.26871052 | I17: =IFERROR(I14*I15*I16,"n/m") -> 0.26093277 | ... K17: =IFERROR(K14*K15*K16,"n/m") -> 0.1896299
A19: FIVE STAGE MODEL
A20: Tax Burden (Net Income ÷ PBT) | B20: =IFERROR(B9/B5,"n/m") -> 0.66923302 | C20: =IFERROR(C9/C5,"n/m") -> 0.67003655 | D20: =IFERROR(D9/D5,"n/m") -> 0.66743516 | E20: =IFERROR(E9/E5,"n/m") -> 0.70524228 | F20: =IFERROR(F9/F5,"n/m") -> 0.68105457 | G20: =IFERROR(G9/G5,"n/m") -> 0.70744419 | H20: =IFERROR(H9/H5,"n/m") -> 0.66430721 | I20: =IFERROR(I9/I5,"n/m") -> 0.78609777 | ... K20: =IFERROR(K9/K5,"n/m") -> 0.77157801
